#for inner try there is no except block 


# try:
#     try:
#        print('inner try')
# except:
#     print('except')